<?xml version="1.0"?>
<robot name="ecoweeder">

  <!-- Materials -->
  <material name="white">
    <color rgba="1 1 1 1"/>
  </material>
  <material name="green">
    <color rgba="0 0.8 0 1"/>
  </material>
  <material name="black">
    <color rgba="0.1 0.1 0.1 1"/>
  </material>
  <material name="yellow">
    <color rgba="1 1 0 1"/>
  </material>

  <!-- Base Link -->
  <link name="base_link">
  </link>

  <!-- Chassis -->
  <joint name="chassis_joint" type="fixed">
    <parent link="base_link"/>
    <child link="chassis"/>
    <origin xyz="0 0 0.1"/>
  </joint>

  <link name="chassis">
    <visual>
      <origin xyz="0 0 0.1"/>
      <geometry>
        <box size="0.8 0.5 0.3"/>
      </geometry>
      <material name="white"/>
    </visual>
    <visual>
      <origin xyz="0 0 0.05"/>
      <geometry>
        <box size="0.82 0.52 0.1"/>
      </geometry>
      <material name="green"/>
    </visual>
    <collision>
      <origin xyz="0 0 0.1"/>
      <geometry>
        <box size="0.8 0.5 0.3"/>
      </geometry>
    </collision>
    <inertial>
      <mass value="20.0"/>
      <inertia ixx="0.5" ixy="0" ixz="0" iyy="1.0" iyz="0" izz="1.0"/>
    </inertial>
  </link>

  <!-- Front Left Wheel -->
  <link name="front_left_wheel">
    <visual>
      <geometry>
        <cylinder radius="0.15" length="0.1"/>
      </geometry>
      <material name="black"/>
    </visual>
    <collision>
      <geometry>
        <cylinder radius="0.15" length="0.1"/>
      </geometry>
    </collision>
    <inertial>
      <mass value="2.0"/>
      <inertia ixx="0.01" ixy="0" ixz="0" iyy="0.01" iyz="0" izz="0.01"/>
    </inertial>
  </link>

  <joint name="front_left_wheel_joint" type="continuous">
    <parent link="chassis"/>
    <child link="front_left_wheel"/>
    <origin xyz="0.25 0.3 0" rpy="-1.5708 0 0"/>
    <axis xyz="0 0 1"/>
  </joint>

  <!-- Front Right Wheel -->
  <link name="front_right_wheel">
    <visual>
      <geometry>
        <cylinder radius="0.15" length="0.1"/>
      </geometry>
      <material name="black"/>
    </visual>
    <collision>
      <geometry>
        <cylinder radius="0.15" length="0.1"/>
      </geometry>
    </collision>
    <inertial>
      <mass value="2.0"/>
      <inertia ixx="0.01" ixy="0" ixz="0" iyy="0.01" iyz="0" izz="0.01"/>
    </inertial>
  </link>

  <joint name="front_right_wheel_joint" type="continuous">
    <parent link="chassis"/>
    <child link="front_right_wheel"/>
    <origin xyz="0.25 -0.3 0" rpy="-1.5708 0 0"/>
    <axis xyz="0 0 1"/>
  </joint>

  <!-- Rear Left Wheel -->
  <link name="rear_left_wheel">
    <visual>
      <geometry>
        <cylinder radius="0.15" length="0.1"/>
      </geometry>
      <material name="black"/>
    </visual>
    <collision>
      <geometry>
        <cylinder radius="0.15" length="0.1"/>
      </geometry>
    </collision>
    <inertial>
      <mass value="2.0"/>
      <inertia ixx="0.01" ixy="0" ixz="0" iyy="0.01" iyz="0" izz="0.01"/>
    </inertial>
  </link>

  <joint name="rear_left_wheel_joint" type="continuous">
    <parent link="chassis"/>
    <child link="rear_left_wheel"/>
    <origin xyz="-0.25 0.3 0" rpy="-1.5708 0 0"/>
    <axis xyz="0 0 1"/>
  </joint>

  <!-- Rear Right Wheel -->
  <link name="rear_right_wheel">
    <visual>
      <geometry>
        <cylinder radius="0.15" length="0.1"/>
      </geometry>
      <material name="black"/>
    </visual>
    <collision>
      <geometry>
        <cylinder radius="0.15" length="0.1"/>
      </geometry>
    </collision>
    <inertial>
      <mass value="2.0"/>
      <inertia ixx="0.01" ixy="0" ixz="0" iyy="0.01" iyz="0" izz="0.01"/>
    </inertial>
  </link>

  <joint name="rear_right_wheel_joint" type="continuous">
    <parent link="chassis"/>
    <child link="rear_right_wheel"/>
    <origin xyz="-0.25 -0.3 0" rpy="-1.5708 0 0"/>
    <axis xyz="0 0 1"/>
  </joint>

  <!-- Weeding Tool (Yellow part at front) -->
  <link name="weeder_tool">
    <visual>
      <geometry>
        <box size="0.2 0.6 0.1"/>
      </geometry>
      <material name="yellow"/>
    </visual>
    <collision>
      <geometry>
        <box size="0.2 0.6 0.1"/>
      </geometry>
    </collision>
    <inertial>
      <mass value="1.0"/>
      <inertia ixx="0.01" ixy="0" ixz="0" iyy="0.01" iyz="0" izz="0.01"/>
    </inertial>
  </link>

  <joint name="weeder_joint" type="fixed">
    <parent link="chassis"/>
    <child link="weeder_tool"/>
    <origin xyz="0.5 0 0" rpy="0 0 0"/>
  </joint>

  <!-- Sensor Tower -->
  <link name="sensor_tower">
    <visual>
      <geometry>
        <cylinder radius="0.05" length="0.4"/>
      </geometry>
      <material name="black"/>
    </visual>
  </link>

  <joint name="sensor_tower_joint" type="fixed">
    <parent link="chassis"/>
    <child link="sensor_tower"/>
    <origin xyz="0.2 0 0.4" rpy="0 0 0"/>
  </joint>

  <!-- Gazebo Plugins -->
  <gazebo>
    <plugin
      filename="gz-sim-diff-drive-system"
      name="gz::sim::systems::DiffDrive">
      <left_joint>front_left_wheel_joint</left_joint>
      <left_joint>rear_left_wheel_joint</left_joint>
      <right_joint>front_right_wheel_joint</right_joint>
      <right_joint>rear_right_wheel_joint</right_joint>
      <wheel_separation>0.6</wheel_separation>
      <wheel_radius>0.15</wheel_radius>
      <odom_publish_frequency>10</odom_publish_frequency>
      <topic>cmd_vel</topic>
      <odom_topic>odom</odom_topic>
      <tf_topic>tf</tf_topic>
      <frame_id>odom</frame_id>
      <child_frame_id>base_link</child_frame_id>
    </plugin>

    <plugin
      filename="gz-sim-joint-state-publisher-system"
      name="gz::sim::systems::JointStatePublisher">
    </plugin>
  </gazebo>

</robot>
